<?xml version="1.0" encoding="utf-8"?>
<!-- This URDF was automatically created by SolidWorks to URDF Exporter! Originally created by Stephen Brawner (brawner@gmail.com) 
     Commit Version: 1.6.0-4-g7f85cfe  Build Version: 1.6.7995.38578
     For more information, please see http://wiki.ros.org/sw_urdf_exporter -->
<robot
  name="Assem 2">
  <link
    name="base_link">
    <inertial>
      <origin
        xyz="0.067406 0.0019312 0.021326"
        rpy="0 0 0" />
      <mass
        value="0.59569" />
      <inertia
        ixx="0.0017912"
        ixy="7.7075E-05"
        ixz="0.00031985"
        iyy="0.0029313"
        iyz="2.4441E-05"
        izz="0.0041728" />
    </inertial>
    <visual>
      <origin
        xyz="0 0 0"
        rpy="0 0 0" />
      <geometry>
        <mesh
          filename="package://my_bot/description/meshes/base_link.STL" />
      </geometry>
      <material
        name="">
        <color
          rgba="0.25098 0.25098 0.25098 1" />
      </material>
    </visual>
    <collision>
      <origin
        xyz="0 0 0"
        rpy="0 0 0" />
      <geometry>
        <mesh
          filename="package://my_bot/description/meshes/base_link.STL" />
      </geometry>
    </collision>
  </link>
  <link
    name="left_wheel">
    <inertial>
      <origin
        xyz="0 0 -1.3878E-17"
        rpy="0 0 0" />
      <mass
        value="0.10164" />
      <inertia
        ixx="3.2133E-05"
        ixy="3.0279E-19"
        ixz="3.0269E-21"
        iyy="5.3678E-05"
        iyz="-4.2598E-21"
        izz="3.2133E-05" />
    </inertial>
    <visual>
      <origin
        xyz="0 0 0"
        rpy="0 0 0" />
      <geometry>
        <mesh
          filename="package://my_bot/description/meshes/left_wheel.STL" />
      </geometry>
      <material
        name="">
        <color
          rgba="0 0 0.50196 1" />
      </material>
    </visual>
    <collision>
      <origin
        xyz="0 0 0"
        rpy="0 0 0" />
      <geometry>
        <mesh
          filename="package://my_bot/description/meshes/left_wheel.STL" />
      </geometry>
    </collision>
  </link>
  <joint
    name="left_wheel_joint"
    type="continuous">
    <origin
      xyz="0.001 0.13017 0.0235"
      rpy="0 0 0" />
    <parent
      link="base_link" />
    <child
      link="left_wheel" />
    <axis
      xyz="0 1 0" />
  </joint>
  <link
    name="right_wheel">
    <inertial>
      <origin
        xyz="6.9389E-18 0 0"
        rpy="0 0 0" />
      <mass
        value="0.10164" />
      <inertia
        ixx="3.2133E-05"
        ixy="-8.6646E-22"
        ixz="2.1621E-21"
        iyy="5.3678E-05"
        iyz="4.6922E-21"
        izz="3.2133E-05" />
    </inertial>
    <visual>
      <origin
        xyz="0 0 0"
        rpy="0 0 0" />
      <geometry>
        <mesh
          filename="package://my_bot/description/meshes/right_wheel.STL" />
      </geometry>
      <material
        name="">
        <color
          rgba="0 0 0.50196 1" />
      </material>
    </visual>
    <collision>
      <origin
        xyz="0 0 0"
        rpy="0 0 0" />
      <geometry>
        <mesh
          filename="package://my_bot/description/meshes/right_wheel.STL" />
      </geometry>
    </collision>
  </link>
  <joint
    name="right_wheel_joint"
    type="continuous">
    <origin
      xyz="0.001 -0.13017 0.0235"
      rpy="0 0 0" />
    <parent
      link="base_link" />
    <child
      link="right_wheel" />
    <axis
      xyz="0 -1 0" />
  </joint>
  <link
    name="laser_frame">
    <inertial>
      <origin
        xyz="-0.0067665 9.1926E-05 -0.0083819"
        rpy="0 0 0" />
      <mass
        value="0.17402" />
      <inertia
        ixx="8.0412E-05"
        ixy="-1.0487E-07"
        ixz="-2.0693E-05"
        iyy="0.00012563"
        iyz="4.0429E-07"
        izz="0.0001436" />
    </inertial>
    <visual>
      <origin
        xyz="0 0 0"
        rpy="0 0 0" />
      <geometry>
        <mesh
          filename="package://my_bot/description/meshes/laser_frame.STL" />
      </geometry>
      <material
        name="">
        <color
          rgba="1 1 1 1" />
      </material>
    </visual>
    <collision>
      <origin
        xyz="0 0 0"
        rpy="0 0 0" />
      <geometry>
        <mesh
          filename="package://my_bot/description/meshes/laser_frame.STL" />
      </geometry>
    </collision>
  </link>
  <joint
    name="laser_joint"
    type="fixed">
    <origin
      xyz="0.1048 0 0.091825"
      rpy="0 0 0" />
    <parent
      link="base_link" />
    <child
      link="laser_frame" />
    <axis
      xyz="0 0 0" />
  </joint>
  <link
    name="camera_link">
    <inertial>
      <origin
        xyz="-0.010597 -1.8404E-05 0.0029121"
        rpy="0 0 0" />
      <mass
        value="0.0057972" />
      <inertia
        ixx="6.4641E-07"
        ixy="3.883E-13"
        ixz="-1.0375E-09"
        iyy="2.7217E-07"
        iyz="2.3413E-10"
        izz="3.8601E-07" />
    </inertial>
    <visual>
      <origin
        xyz="0 0 0"
        rpy="0 0 0" />
      <geometry>
        <mesh
          filename="package://my_bot/description/meshes/camera_link.STL" />
      </geometry>
      <material
        name="">
        <color
          rgba="0.25098 0.25098 0.25098 1" />
      </material>
    </visual>
    <collision>
      <origin
        xyz="0 0 0"
        rpy="0 0 0" />
      <geometry>
        <mesh
          filename="package://my_bot/description/meshes/camera_link.STL" />
      </geometry>
    </collision>
  </link>
  <joint
    name="camera_joint"
    type="fixed">
    <origin
      xyz="0.16129 0 0.029575"
      rpy="0 0 0" />
    <parent
      link="base_link" />
    <child
      link="camera_link" />
    <axis
      xyz="0 0 0" />
  </joint>
  <link
    name="caster_wheel">
    <inertial>
      <origin
        xyz="0 1.3878E-17 1.3878E-17"
        rpy="0 0 0" />
      <mass
        value="0.0083657" />
      <inertia
        ixx="1.3493E-07"
        ixy="-4.097E-24"
        ixz="0"
        iyy="1.3493E-07"
        iyz="5.9132E-39"
        izz="1.3493E-07" />
    </inertial>
    <visual>
      <origin
        xyz="0 0 0"
        rpy="0 0 0" />
      <geometry>
        <mesh
          filename="package://my_bot/description/meshes/caster_wheel.STL" />
      </geometry>
      <material
        name="">
        <color
          rgba="0.52941 0.54902 0.54902 1" />
      </material>
    </visual>
    <collision>
      <origin
        xyz="0 0 0"
        rpy="0 0 0" />
      <geometry>
        <mesh
          filename="package://my_bot/description/meshes/caster_wheel.STL" />
      </geometry>
    </collision>
  </link>
  <joint
    name="caster_wheel_joint"
    type="fixed">
    <origin
      xyz="0.18465 0 -0.00265"
      rpy="1.5708 0 0" />
    <parent
      link="base_link" />
    <child
      link="caster_wheel" />
    <axis
      xyz="0 0 0" />
    <dynamics
      friction="0.001" />
  </joint>
</robot>