<?xml version='1.0' encoding='utf-8'?>
<robot name="Assem">
    <link name="rplidar_main_По-умолчанию">
        <inertial>
            <origin xyz="-0.04153328074084977 -0.034908076976191825 0.03526812958776807" rpy="0.0 -0.0 0.0" />
            <mass value="1.339299707757665" />
            <inertia ixx="0.0006188597221929368" iyy="0.0009668556516496188" izz="0.0011051914360182581" ixy="-8.071252421172626e-07" iyz="3.111448005611861e-06" ixz="-0.00015925740428234664" />
        </inertial>
        <visual name="rplidar_main_По-умолчанию_visual">
            <origin xyz="-0.049016750624191786 -0.0010208252626294368 -0.012916824130788047" rpy="-3.141592653589793 3.1225022567582534e-17 3.141592653589793" />
            <geometry>
                <mesh filename="meshes/rplidar_main_По-умолчанию.stl" scale="0.001 0.001 0.001" />
            </geometry>
        </visual>
        <collision name="rplidar_main_По-умолчанию_collision">
            <origin xyz="-0.049016750624191786 -0.0010208252626294368 -0.012916824130788047" rpy="-3.141592653589793 3.1225022567582534e-17 3.141592653589793" />
            <geometry>
                <mesh filename="meshes/rplidar_main_По-умолчанию.stl" scale="0.001 0.001 0.001" />
            </geometry>
        </collision>
    </link>
    <link name="Caster-Wheel">
        <inertial>
            <origin xyz="0.08999999806786084 3.08731786802241e-09 -1.854927553779362e-09" rpy="0.0 -0.0 0.0" />
            <mass value="0.008419367021437507" />
            <inertia ixx="1.3579597068875894e-07" iyy="1.3579597068878605e-07" izz="1.3579597068878605e-07" ixy="0.0" iyz="-1.3552527156068805e-20" ixz="0.0" />
        </inertial>
        <visual name="Caster-Wheel_visual">
            <origin xyz="0.08623678097548926 0.04068443996386147 -0.038637690490664366" rpy="3.141592653589793 -3.035766082959413e-18 1.5707963267948966" />
            <geometry>
                <mesh filename="meshes/Caster-Wheel.stl" scale="0.001 0.001 0.001" />
            </geometry>
        </visual>
        <collision name="Caster-Wheel_collision">
            <origin xyz="0.08623678097548926 0.04068443996386147 -0.038637690490664366" rpy="3.141592653589793 -3.035766082959413e-18 1.5707963267948966" />
            <geometry>
                <mesh filename="meshes/Caster-Wheel.stl" scale="0.001 0.001 0.001" />
            </geometry>
        </collision>
    </link>
    <link name="Blue-Wheels">
        <inertial>
            <origin xyz="4.571557754573519e-09 1.8549276070700672e-09 0.019500003087316968" rpy="0.0 -0.0 0.0" />
            <mass value="0.6512177959195157" />
            <inertia ixx="0.0002058797927724657" iyy="0.0002058797927724657" izz="0.0003439243984699903" ixy="-4.3368086899420086e-19" iyz="1.2232744496681935e-18" ixz="4.0660576309368165e-18" />
        </inertial>
        <visual name="Blue-Wheels_visual">
            <origin xyz="4.571558172017376e-09 0.1309168278406404 0.16497082526262663" rpy="3.141592653589793 -1.2686402961170398 -1.2246467991472608e-16" />
            <geometry>
                <mesh filename="meshes/Blue-Wheels.stl" scale="0.001 0.001 0.001" />
            </geometry>
        </visual>
        <collision name="Blue-Wheels_collision">
            <origin xyz="4.571558172017376e-09 0.1309168278406404 0.16497082526262663" rpy="3.141592653589793 -1.2686402961170398 -1.2246467991472608e-16" />
            <geometry>
                <mesh filename="meshes/Blue-Wheels.stl" scale="0.001 0.001 0.001" />
            </geometry>
        </collision>
    </link>
    <link name="Base-Plate_Simplified-Box">
        <inertial>
            <origin xyz="0.004605737369248436 0.021931162811598667 -0.026848881351487854" rpy="0.0 -0.0 0.0" />
            <mass value="3.7409488741698054" />
            <inertia ixx="0.011246398992742435" iyy="0.018408488534026643" izz="0.02620495603985091" ixy="0.00048404388252989517" iyz="0.00015348767561477325" ixz="0.002008664102083953" />
        </inertial>
        <visual name="Base-Plate_Simplified-Box_visual">
            <origin xyz="0.05299994457155578 -0.015795825262629216 -0.03541682413078819" rpy="7.059095485558965e-15 1.8701136533192588e-47 -2.6492256085004303e-33" />
            <geometry>
                <mesh filename="meshes/Base-Plate_Simplified-Box.stl" scale="0.001 0.001 0.001" />
            </geometry>
        </visual>
        <collision name="Base-Plate_Simplified-Box_collision">
            <origin xyz="0.05299994457155578 -0.015795825262629216 -0.03541682413078819" rpy="7.059095485558965e-15 1.8701136533192588e-47 -2.6492256085004303e-33" />
            <geometry>
                <mesh filename="meshes/Base-Plate_Simplified-Box.stl" scale="0.001 0.001 0.001" />
            </geometry>
        </collision>
    </link>
    <link name="Blue-Wheels">
        <inertial>
            <origin xyz="4.571555676236017e-09 -1.8549276070700672e-09 0.019499996912682355" rpy="0.0 -0.0 0.0" />
            <mass value="0.6512177959195157" />
            <inertia ixx="0.0002058797927725342" iyy="0.00020587979277254115" izz="0.0003439243984700458" ixy="6.071532165918826e-18" iyz="5.554133901572849e-17" ixz="7.052880662911614e-18" />
        </inertial>
        <visual name="Blue-Wheels_visual">
            <origin xyz="4.571557745691735e-09 0.1309168241307852 -0.12597082526262704" rpy="-7.145080809959522e-15 1.268640296117056 -3.141592653589793" />
            <geometry>
                <mesh filename="meshes/Blue-Wheels.stl" scale="0.001 0.001 0.001" />
            </geometry>
        </visual>
        <collision name="Blue-Wheels_collision">
            <origin xyz="4.571557745691735e-09 0.1309168241307852 -0.12597082526262704" rpy="-7.145080809959522e-15 1.268640296117056 -3.141592653589793" />
            <geometry>
                <mesh filename="meshes/Blue-Wheels.stl" scale="0.001 0.001 0.001" />
            </geometry>
        </collision>
    </link>
    <link name="Pi-Cam-Base-Mount">
        <inertial>
            <origin xyz="-0.007687940983207966 -0.014531592994711922 0.004223924224736351" rpy="0.0 -0.0 0.0" />
            <mass value="0.03640662817849758" />
            <inertia ixx="2.8955055742639233e-06" iyy="2.610178586038214e-06" izz="4.5955050107712985e-06" ixy="-4.402339615517271e-09" iyz="-1.41166416815601e-09" ixz="2.126344043364408e-07" />
        </inertial>
        <visual name="Pi-Cam-Base-Mount_visual">
            <origin xyz="-0.019186173172427098 -0.014269388274645448 -0.005308588577329481" rpy="4.1561583797382274e-16 3.7217542573224357e-16 3.141592653589793" />
            <geometry>
                <mesh filename="meshes/Pi-Cam-Base-Mount.stl" scale="0.001 0.001 0.001" />
            </geometry>
        </visual>
        <collision name="Pi-Cam-Base-Mount_collision">
            <origin xyz="-0.019186173172427098 -0.014269388274645448 -0.005308588577329481" rpy="4.1561583797382274e-16 3.7217542573224357e-16 3.141592653589793" />
            <geometry>
                <mesh filename="meshes/Pi-Cam-Base-Mount.stl" scale="0.001 0.001 0.001" />
            </geometry>
        </collision>
    </link>
    <joint name="Base-Plate_Simplified-Box_Rigid-2" type="fixed">
        <origin xyz="0.08384815 0.005450000000000053 -0.007999999999999972" rpy="3.141592653589793 -1.5707963267948895 0" />
        <parent link="Base-Plate_Simplified-Box" />
        <child link="Pi-Cam-Base-Mount" />
    </joint>
    <joint name="Base-Plate_Simplified-Box_Revolute-3" type="continuous">
        <origin xyz="-0.061800060000000025 0.13067500000000018 -0.02467499999999907" rpy="-1.5707963267948892 1.8701136533192588e-47 -2.6492256085004303e-33" />
        <parent link="Base-Plate_Simplified-Box" />
        <child link="Blue-Wheels" />
        <axis xyz="0.0 2.186813770674615e-16 1.0" />
    </joint>
    <joint name="Base-Plate_Simplified-Box_Revolute-4" type="continuous">
        <origin xyz="-0.061800060000000025 -0.09067499999999983 -0.024675000000000634" rpy="1.5707963267949039 1.8701136533192588e-47 -2.6492256085004303e-33" />
        <parent link="Base-Plate_Simplified-Box" />
        <child link="Blue-Wheels" />
        <axis xyz="0.0 2.220446049250312e-16 1.0" />
    </joint>
    <joint name="rplidar_main_По-умолчанию_Rigid-5" type="fixed">
        <origin xyz="-0.07676675 -0.055 0.0" rpy="-7.059095485558965e-15 -0.0 2.649225608499055e-33" />
        <parent link="rplidar_main_По-умолчанию" />
        <child link="Base-Plate_Simplified-Box" />
    </joint>
    <joint name="Base-Plate_Simplified-Box_Rigid-6" type="fixed">
        <origin xyz="0.03492404999999996 0.020000000000000337 -0.04817499999999986" rpy="-3.141592653589786 1.8701136533192588e-47 -2.6492256085004303e-33" />
        <parent link="Base-Plate_Simplified-Box" />
        <child link="Caster-Wheel" />
    </joint>
    <joint name="Lidar-Collision-Model_Rigid-8" type="fixed">
        <origin xyz="0.08253021449809991 0.15301681441020829 0.12346063999999883" rpy="-6.974252452931318e-15 7.400920180010353e-32 -1.7665839505618303e-17" />
        <parent link="Lidar-Collision-Model" />
        <child link="rplidar_main_По-умолчанию" />
    </joint>
    <joint name="Pi-Cam-Base-Mount_Rigid-9" type="fixed">
        <origin xyz="0.008000000000000007 0.0020500000000000006 0.0031750000000000077" rpy="3.141592653589793 -1.5707963267948966 0" />
        <parent link="Pi-Cam-Base-Mount" />
        <child link="Pi-Cam-Collision-File" />
    </joint>
</robot>